<?xml version='1.0' encoding='utf-8'?>
<robot name="double">
    <link name="base">
        <inertial>
            <origin xyz="-5.0882903644930016e-14 0.033905297119097316 0.020682775993718396" rpy="0.0 0.0 0.0" />
            <mass value="0.2737801766240988" />
            <inertia ixx="0.00016679533675185336" iyy="0.0001958750687430902" izz="0.00027398927678538214" ixy="-6.117292614119047e-16" iyz="6.944905548926094e-07" ixz="3.228062278523375e-17" />
        </inertial>
        <visual name="base_visual">
            <origin xyz="0.0 0.0 0.0" rpy="0.0 0.0 0.0" />
            <geometry>
                <mesh filename="meshes/base.stl" scale="0.001 0.001 0.001" />
            </geometry>
        </visual>
        <collision name="base_collision">
            <origin xyz="0.0 0.0 0.0" rpy="0.0 0.0 0.0" />
            <geometry>
                <mesh filename="meshes/base.stl" scale="0.001 0.001 0.001" />
            </geometry>
        </collision>
    </link>
    <link name="link1">
        <inertial>
            <origin xyz="-2.2190295416903779e-10 -0.0955400368710832 -0.006259995602085407" rpy="0.0 -0.0 0.0" />
            <mass value="0.09399409199209499" />
            <inertia ixx="0.00029467377914367196" iyy="1.0510242045380947e-05" izz="0.0002976746822149684" ixy="-2.131063201558736e-14" iyz="8.678538554007516e-06" ixz="6.630251666293837e-17" />
        </inertial>
        <visual name="link1_visual">
            <origin xyz="0.0 -0.023 -0.02" rpy="-1.5707963267948966 -0.0 0.0" />
            <geometry>
                <mesh filename="meshes/link1.stl" scale="0.001 0.001 0.001" />
            </geometry>
        </visual>
        <collision name="link1_collision">
            <origin xyz="0.0 -0.023 -0.02" rpy="-1.5707963267948966 -0.0 0.0" />
            <geometry>
                <mesh filename="meshes/link1.stl" scale="0.001 0.001 0.001" />
            </geometry>
        </collision>
    </link>
    <link name="link2">
        <inertial>
            <origin xyz="-2.2185957555771233e-10 -0.08986164433626702 -0.007499999999999995" rpy="0.0 -0.0 0.0" />
            <mass value="0.08733391541761781" />
            <inertia ixx="0.0002526481818618852" iyy="8.226579043583588e-06" izz="0.0002575997390773079" ixy="-2.100693474766756e-14" iyz="0.0" ixz="1.5063505224990281e-21" />
        </inertial>
        <visual name="link2_visual">
            <origin xyz="0.0 0.147 -0.04" rpy="-1.5707963267948966 -0.0 0.0" />
            <geometry>
                <mesh filename="meshes/link2.stl" scale="0.001 0.001 0.001" />
            </geometry>
        </visual>
        <collision name="link2_collision">
            <origin xyz="0.0 0.147 -0.04" rpy="-1.5707963267948966 -0.0 0.0" />
            <geometry>
                <mesh filename="meshes/link2.stl" scale="0.001 0.001 0.001" />
            </geometry>
        </collision>
    </link>
    <joint name="base_Revolute-1" type="continuous">
        <origin xyz="0.0 -0.02 0.023" rpy="1.5707963267948966 -0.0 0.0" />
        <parent link="base" />
        <child link="link1" />
        <axis xyz="0.0 0.0 1.0" />
    </joint>
    <joint name="link1_Revolute-2" type="continuous">
        <origin xyz="0.0 -0.17 0.02" rpy="0.0 -0.0 0.0" />
        <parent link="link1" />
        <child link="link2" />
        <axis xyz="0.0 0.0 1.0" />
    </joint>
</robot>